Creating Python virtual environment "app/backend/.venv"...
Installing dependencies from "requirements.txt" into virtual environment (in quiet mode)...

Restoring frontend npm packages


up to date, audited 251 packages in 2s

40 packages are looking for funding
  run `npm fund` for details

found 0 vulnerabilities

Building frontend


> frontend@0.0.0 build
> tsc -b && vite build

vite v5.4.8 building for production...
transforming...
node_modules/framer-motion/dist/es/components/AnimatePresence/index.mjs (1:0): Error when using sourcemap for reporting an error: Can't resolve original location of error.
node_modules/framer-motion/dist/es/motion/index.mjs (1:0): Error when using sourcemap for reporting an error: Can't resolve original location of error.
✓ 1969 modules transformed.
rendering chunks...
computing gzip size...
../backend/static/index.html                   0.47 kB │ gzip:   0.31 kB
../backend/static/assets/index-MbNbqoGC.css   14.11 kB │ gzip:   3.75 kB
../backend/static/assets/index-BrCwpeIS.js   398.36 kB │ gzip: 127.20 kB │ map: 1,477.23 kB
✓ built in 12.57s

Starting backend

INFO:voicerag:Running in development mode, loading from .env file
INFO:voicerag:Using AzureDeveloperCliCredential with tenant_id 84c31ca0-ac3b-4eae-ad11-519d80233e6f
INFO:azure.identity._internal.decorators:AzureDeveloperCliCredential.get_token_info succeeded
INFO:azure.identity._internal.decorators:AzureDeveloperCliCredential.get_token succeeded
ERROR:asyncio:unhandled exception during asyncio.run() shutdown
task: <Task finished name='Task-1' coro=<_run_app() done, defined at /workspaces/aisearch-openai-rag-audio/.venv/lib/python3.12/site-packages/aiohttp/web.py:303> exception=OSError(98, "error while attempting to bind on address ('::1', 8765, 0, 0): [errno 98] address already in use")>
Traceback (most recent call last):
  File "/workspaces/aisearch-openai-rag-audio/.venv/lib/python3.12/site-packages/aiohttp/web.py", line 544, in run_app
    loop.run_until_complete(main_task)
  File "/usr/local/lib/python3.12/asyncio/base_events.py", line 687, in run_until_complete
    return future.result()
           ^^^^^^^^^^^^^^^
  File "/workspaces/aisearch-openai-rag-audio/.venv/lib/python3.12/site-packages/aiohttp/web.py", line 448, in _run_app
    await site.start()
  File "/workspaces/aisearch-openai-rag-audio/.venv/lib/python3.12/site-packages/aiohttp/web_runner.py", line 119, in start
    self._server = await loop.create_server(
                   ^^^^^^^^^^^^^^^^^^^^^^^^^
  File "/usr/local/lib/python3.12/asyncio/base_events.py", line 1571, in create_server
    raise OSError(err.errno, msg) from None
OSError: [Errno 98] error while attempting to bind on address ('::1', 8765, 0, 0): [errno 98] address already in use
Traceback (most recent call last):
  File "/workspaces/aisearch-openai-rag-audio/app/backend/app.py", line 239, in <module>
    web.run_app(create_app(), host=host, port=port)
  File "/workspaces/aisearch-openai-rag-audio/.venv/lib/python3.12/site-packages/aiohttp/web.py", line 544, in run_app
    loop.run_until_complete(main_task)
  File "/usr/local/lib/python3.12/asyncio/base_events.py", line 687, in run_until_complete
    return future.result()
           ^^^^^^^^^^^^^^^
  File "/workspaces/aisearch-openai-rag-audio/.venv/lib/python3.12/site-packages/aiohttp/web.py", line 448, in _run_app
    await site.start()
  File "/workspaces/aisearch-openai-rag-audio/.venv/lib/python3.12/site-packages/aiohttp/web_runner.py", line 119, in start
    self._server = await loop.create_server(
                   ^^^^^^^^^^^^^^^^^^^^^^^^^
  File "/usr/local/lib/python3.12/asyncio/base_events.py", line 1571, in create_server
    raise OSError(err.errno, msg) from None
OSError: [Errno 98] error while attempting to bind on address ('::1', 8765, 0, 0): [errno 98] address already in use
Failed to start backend
